This issue was reported upstream:
https://github.com/cherrypy/cherrypy/issues/2044

--- cherrypy-18.10.0/pytest.ini
+++ cherrypy-18.10.0/pytest.ini
@@ -63,6 +63,10 @@ filterwarnings =
   # TODO: connection properly.
   ignore:unclosed <socket.socket fd=:ResourceWarning
 
+  # Python 3.13 no longer ignores IOBase errors raised by the close(),
+  # which exposed a possible race condition in test_conn tests.
+  ignore:Exception ignored in. <function IOBase.__del__:pytest.PytestUnraisableExceptionWarning
+
 junit_duration_report = call
 junit_family = xunit2
 junit_suite_name = cherrypy_test_suite
